{
  "xsize": 16,
  "zsize": 16,
  "slices": [
    [
      "################",
      "################",
      "################",
      "################",
      "################",
      "################",
      "######1#########",
      "################",
      "################",
      "################",
      "##########  ####",
      "##########  ####",
      "##########  ####",
      "##########cc####",
      "################",
      "################"
    ],
    [
      "#aa#aa#aa#aa#aa#",
      "a     #        a",
      "a     #        a",
      "#C             #",
      "a     #        a",
      "a     #        a",
      "#######        #",
      "a    ##        a",
      "a    ##   cc   a",
      "#    ##  :dd:  #",
      "a     #  :  :  a",
      "a        :  :  a",
      "#    F#  :  :  #",
      "a    F#        a",
      "a     #        a",
      "#aa#aa#aa#aa#aa#"
    ],
    [
      "#aa#aa#aa#aa#aa#",
      "a     #        a",
      "a     #        a",
      "#              #",
      "a     #        a",
      "a     #        a",
      "##:::##T       #",
      "a     #        a",
      "a    *#        a",
      "#    *#   cc   #",
      "a     #   dd   a",
      "a              a",
      "#     #        #",
      "a     #        a",
      "a     #        a",
      "#aa#aa#aa#aa#aa#"
    ],
    [
      "#aa#aa#aa#aa#aa#",
      "a     #        a",
      "a     #        a",
      "#     #        #",
      "a     #        a",
      "a     #        a",
      "#######        #",
      "a     #        a",
      "a     #        a",
      "#     #        #",
      "a     #   cc   a",
      "a     #   dd   a",
      "#     #        #",
      "a     #        a",
      "a     #        a",
      "#aa#aa#aa#aa#aa#"
    ],
    [
      "################",
      "################",
      "################",
      "################",
      "################",
      "################",
      "################",
      "################",
      "##########  ####",
      "##########  ####",
      "##########  ####",
      "##########cc####",
      "################",
      "################",
      "################",
      "################"
    ],
    [
      "################",
      "################",
      "################",
      "################",
      "################",
      "################",
      "################",
      "################",
      "################",
      "##########  ####",
      "##########  ####",
      "##########  ####",
      "##########cc####",
      "################",
      "################",
      "################"
    ]
  ]
}