{
  "xsize": 16,
  "zsize": 16,
  "palette": {
    "palette": [
      {
        "char": " ",
        "block": "minecraft:air"
      },
      {
        "char": "b",
        "block": "immersive_weathering:plate_iron"
      },
      {
        "char": "c",
        "block": "minecraft:spruce_planks"
      },
      {
        "char": "d",
        "block": "minecraft:birch_log[axis=x]"
      },
      {
        "char": "e",
        "block": "minecraft:orange_wool"
      },
      {
        "char": "f",
        "block": "minecraft:structure_void"
      },
      {
        "char": "g",
        "block": "minecraft:yellow_wool"
      },
      {
        "char": "h",
        "block": "minecraft:repeater[delay=2,facing=east,locked=false,powered=false]"
      },
      {
        "char": "i",
        "block": "minecraft:redstone_wire[east=side,north=none,power=0,south=none,west=side]"
      },
      {
        "char": "j",
        "block": "minecraft:gray_glazed_terracotta[facing=east]"
      },
      {
        "char": "k",
        "block": "minecraft:redstone_torch[lit=true]"
      },
      {
        "char": "l",
        "block": "minecraft:purple_wool"
      },
      {
        "char": "m",
        "block": "minecraft:dropper[facing=west,triggered=false]"
      },
      {
        "char": "n",
        "block": "minecraft:redstone_wire[east=up,north=none,power=15,south=none,west=side]"
      },
      {
        "char": "o",
        "block": "minecraft:magenta_wool"
      },
      {
        "char": "p",
        "block": "minecraft:redstone_wire[east=side,north=none,power=0,south=side,west=none]"
      },
      {
        "char": "q",
        "block": "minecraft:redstone_wire[east=up,north=side,power=0,south=none,west=none]"
      },
      {
        "char": "r",
        "block": "minecraft:redstone_wire[east=up,north=none,power=14,south=none,west=side]"
      },
      {
        "char": "s",
        "block": "minecraft:redstone_wire[east=none,north=side,power=0,south=up,west=none]"
      },
      {
        "char": "t",
        "block": "minecraft:redstone_block"
      },
      {
        "char": "u",
        "block": "minecraft:redstone_wire[east=side,north=none,power=13,south=none,west=side]"
      },
      {
        "char": "v",
        "block": "minecraft:gray_glazed_terracotta[facing=north]"
      },
      {
        "char": "w",
        "block": "minecraft:redstone_wire[east=none,north=side,power=0,south=side,west=none]"
      },
      {
        "char": "x",
        "block": "minecraft:redstone_wire[east=side,north=side,power=0,south=none,west=none]"
      },
      {
        "char": "y",
        "block": "minecraft:obsidian"
      },
      {
        "char": "z",
        "block": "minecraft:repeater[delay=4,facing=west,locked=false,powered=false]"
      },
      {
        "char": "A",
        "block": "minecraft:redstone_wall_torch[facing=south,lit=true]"
      },
      {
        "char": "B",
        "block": "minecraft:piston[extended=true,facing=east]"
      },
      {
        "char": "D",
        "block": "minecraft:piston_head[facing=east,short=false,type=normal]"
      },
      {
        "char": "E",
        "block": "minecraft:redstone_wire[east=none,north=up,power=0,south=none,west=side]"
      },
      {
        "char": "F",
        "block": "minecraft:redstone_wire[east=side,north=none,power=12,south=none,west=side]"
      },
      {
        "char": "G",
        "block": "minecraft:spruce_slab[type=top,waterlogged=false]"
      }
    ]
  },
  "slices": [
    [
      "fffb            ",
      "fffbbbb         ",
      "fffbbbbb        ",
      "fffbbbbbbb      ",
      "fffbbbbbbbb     ",
      "fffbbbbbbbbb    ",
      "bbbbbbbbbbbbb   ",
      "bbbbbbbbbbbbb   ",
      "bbbbbbbbbbbbbb  ",
      "bbbbbbbbbbbbbbb ",
      "bbbbbbbbbbbbbbb ",
      "bbbbbbbbbbbbbbb ",
      "bbbbbbbbbbbbbbbb",
      "bbbbbbbbbbbbbbbb",
      "bbbbbbbbbbbbbbbb",
      "bbbbbbbbbbbbbbbb"
    ],
    [
      "fffb            ",
      "fffbbbb         ",
      "yffbbbbb        ",
      "fffbbbbbbb      ",
      "fffbbbbbbbb     ",
      "fffbbbbbbbbb    ",
      "bbbbbbbbbbbbb   ",
      "bbbbbbbbbbbbb   ",
      "bbbbbbbbbbbbbb  ",
      "bbbbbbbbbbbbbbb ",
      "bbbbbbbbbbbbbbb ",
      "bbbbbbbbbbbbbbb ",
      "bbbbbbbbbbbbbbbb",
      "bbbbbbbbbbbbbbbb",
      "bbbbbbbbbbbbbbbb",
      "bbbbbbbbbbbbbbbb"
    ],
    [
      "lffb            ",
      "fffbbbb         ",
      "fyfbbbbb        ",
      "fffbbbbbbb      ",
      "fffbbbbbbbb     ",
      "fffbbbbbbbbb    ",
      "bbbbbbbbbbbbb   ",
      "bbbbbbbbbbbbb   ",
      "bbbbbbbbbbbbbb  ",
      "bbbbbbbbbbbbbbb ",
      "bbbbbbbbbbbbbbb ",
      "bbbbbbbbbbbbbbb ",
      "bbbbbbbbbbbbbbbb",
      "bbbbbbbbbbbbbbbb",
      "bbbbbbbbbbbbbbbb",
      "bbbbbbbbbbbbbbbb"
    ],
    [
      "zlfb            ",
      "fAfbbbb         ",
      "fBDbbbbb        ",
      "fffbbbbbbb      ",
      "fffbbbbbbbb     ",
      "fffbbbbbbbbb    ",
      "bbbbbbbbbbbbb   ",
      "bbbbbbbbbbbbb   ",
      "bbbbbbbbbbbbbb  ",
      "bbbbbbbbbbbbbbb ",
      "bbbbbbbbbbbbbbb ",
      "bbbbbbbbbbbbbbb ",
      "bbbbbbbbbbbbbbbb",
      "bbbbbbbbbbbbbbbb",
      "bbbbbbbbbbbbbbbb",
      "bbbbbbbbbbbbbbbb"
    ],
    [
      "fffb            ",
      "fffbbbb         ",
      "fffbbbbb        ",
      "fffbbbbbbb      ",
      "fffbbbbbbbb     ",
      "eefbbbbbbbbb    ",
      "bbbbbbbbbbbbb   ",
      "bbbbbbbbbbbbb   ",
      "bbbbbbbbbbbbbb  ",
      "bbbbbbbbbbbbbbb ",
      "bbbbbbbbbbbbbbb ",
      "bbbbbbbbbbbbbbb ",
      "bbbbbbbbbbbbbbbb",
      "bbbbbbbbbbbbbbbb",
      "bbbbbbbbbbbbbbbb",
      "bbbbbbbbbbbbbbbb"
    ],
    [
      "gffb           c",
      "BDfbbbb         ",
      "fffbbbbb        ",
      "fffbbbbbbb      ",
      "fefbbbbbbbb     ",
      "iEfbbbbbbbbb    ",
      "bbbbbbbbbbbbb   ",
      "bbbbbbbbbbbbb   ",
      "bbbbbbbbbbbbbb  ",
      "bbbbbbbbbbbbbbb ",
      "bbbbbbbbbbbbbbb ",
      "bbbbbbbbbbbbbbb ",
      "bbbbbbbbbbbbbbbb",
      "bbbbbbbbbbbbbbbb",
      "bbbbbbbbbbbbbbbb",
      "bbbbbbbbbbbbbbbb"
    ],
    [
      "Fbbb            ",
      "vjfbbbb         ",
      "fyfcccbb        ",
      "fvccccccbb      ",
      "jwcccccccbb     ",
      "cGcccccccccb    ",
      "cccccccccccbb   ",
      "ccccccccccccb   ",
      "cccccccccccccb  ",
      "cccccccccccccbb ",
      "ccccccccccccccb ",
      "ccccccccccccccb ",
      "ccccccccccccccbb",
      "cccccccccccccccb",
      "cccccccccccccccb",
      "cccccccccccccccb"
    ]
  ]
}