{
  "xsize": 16,
  "zsize": 16,
  "palette": {
    "palette": [
      {
        "char": " ",
        "block": "minecraft:air"
      },
      {
        "char": "b",
        "block": "minecraft:structure_void"
      },
      {
        "char": "c",
        "block": "immersive_weathering:plate_iron"
      },
      {
        "char": "d",
        "block": "minecraft:gray_glazed_terracotta[facing=east]"
      },
      {
        "char": "e",
        "block": "minecraft:piston_head[facing=west,short=false,type=normal]"
      },
      {
        "char": "f",
        "block": "minecraft:piston[extended=true,facing=west]"
      },
      {
        "char": "g",
        "block": "minecraft:blue_wool"
      },
      {
        "char": "h",
        "block": "minecraft:redstone_wire[east=none,north=side,power=14,south=up,west=none]"
      },
      {
        "char": "i",
        "block": "minecraft:gray_glazed_terracotta[facing=south]"
      },
      {
        "char": "j",
        "block": "minecraft:redstone_wire[east=side,north=none,power=14,south=none,west=up]"
      },
      {
        "char": "k",
        "block": "minecraft:redstone_wire[east=none,north=side,power=13,south=none,west=side]"
      },
      {
        "char": "l",
        "block": "immersive_weathering:cut_iron"
      },
      {
        "char": "m",
        "block": "minecraft:redstone_wire[east=side,north=side,power=15,south=side,west=none]"
      },
      {
        "char": "n",
        "block": "minecraft:redstone_block"
      },
      {
        "char": "o",
        "block": "minecraft:oak_wall_sign[facing=south,waterlogged=false]"
      },
      {
        "char": "p",
        "block": "minecraft:obsidian"
      },
      {
        "char": "q",
        "block": "minecraft:stone_button[face=wall,facing=east,powered=false]"
      },
      {
        "char": "r",
        "block": "minecraft:oak_wall_sign[facing=east,waterlogged=false]"
      }
    ]
  },
  "slices": [
    [
      "            cbbb",
      "         ccccbdd",
      "        cccccbdb",
      "      ccccbbbbdb",
      "     cccbbbbbblq",
      "    cccbbbbbbblb",
      "   cccbbbbbbbbbb",
      "   ccbbbbbbbbbbb",
      "  ccbbbbbbbbbbbb",
      " cccbbbbbbbbbbbb",
      " ccbbbbbbbbbbbbb",
      " ccbbbbbbbbbbbbb",
      "cccbbbbbbbbbbbbb",
      "ccbbbbbbbbbbbbbb",
      "ccbbbbbbbbbbbbbb",
      "ccbbbbbbbbbbbbbb"
    ],
    [
      "            cbbb",
      "         ccccbdd",
      "        cccccbdb",
      "      ccccbbbbdb",
      "     cccbbbbbblr",
      "    cccbbbbbbblb",
      "   cccbbbbbbbbbb",
      "   ccbbbbbbbbbbb",
      "  ccbbbbbbbbbbbb",
      " cccbbbbbbbbbbbb",
      " ccbbbbbbbbbbbbb",
      " ccbbbbbbbbbbbbb",
      "cccbbbbbbbbbbbbb",
      "ccbbbbbbbbbbbbbb",
      "ccbbbbbbbbbbbbbb",
      "ccbbbbbbbbbbbbbb"
    ],
    [
      "            cbbb",
      "         ccccbdd",
      "        cccccbdb",
      "      ccccbbbbdb",
      "     cccbbbbbbdb",
      "    cccbbbbbbblb",
      "   cccbbbbbbbbbb",
      "   ccbbbbbbbbbbb",
      "  ccbbbbbbbbbbbb",
      " cccbbbbbbbbbbbb",
      " ccbbbbbbbbbbbbb",
      " ccbbbbbbbbbbbbb",
      "cccbbbbbbbbbbbbb",
      "ccbbbbbbbbbbbbbb",
      "ccbbbbbbbbbbbbbb",
      "ccbbbbbbbbbbbbbb"
    ],
    [
      "            cbbb",
      "         ccccbdd",
      "        cccccbdd",
      "      ccccbbbbdd",
      "     cccbbbbbbdd",
      "    cccbbbbbbbll",
      "   cccbbbbbbbbbb",
      "   ccbbbbbbbbbbb",
      "  ccbbbbbbbbbbbb",
      " cccbbbbbbbbbbbb",
      " ccbbbbbbbbbbbbb",
      " ccbbbbbbbbbbbbb",
      "cccbbbbbbbbbbbbb",
      "ccbbbbbbbbbbbbbb",
      "ccbbbbbbbbbbbbbb",
      "ccbbbbbbbbbbbbbb"
    ]
  ]
}